<?xml version="1.0" ?>
<robot name="spot">
    <link name="body">
        <inertial>
            <origin rpy="0 0 0" xyz="0 0 -0.005" />
            <mass value="17" />
            <inertia ixx="0.08" ixy="0" ixz="0" iyy="0.5" iyz="0" izz="0.6" />
        </inertial>
        <visual>
            <geometry>
                <mesh filename="../meshes/body.dae" />
            </geometry>
        </visual>
        <collision>
          <origin rpy="0 0 0" xyz="0 0 0"/>
          <geometry>
            <box size="0.9 0.25 0.22"/>
          </geometry>
        </collision>
    </link>

    <link name="base_link"/>
    <joint name="base_link_joint" type="fixed">
        <origin xyz="0 0 0" rpy="0 0 0" />
        <parent link="body" />
        <child link="base_link" />
    </joint>

    <link name="front_rail"/>
    <joint name="front_rail_joint" type="fixed">
        <origin xyz="0.223 0 0.0805" rpy="0 0 0" />
        <parent link="body" />
        <child link="front_rail" />
    </joint>

    <link name="rear_rail"/>
    <joint name="rear_rail_joint" type="fixed">
        <origin xyz="-0.223 0 0.0805" rpy="0 0 0" />
        <parent link="body" />
        <child link="rear_rail" />
    </joint>
    <link name="front_right_hip">
        <inertial>
            <origin rpy="0 0 0" xyz="0.02 -0.0009 -0.000009" />
            <mass value="1.1" />
            <inertia ixx="0.001" ixy="0.0002" ixz="0.0000004" iyy="0.002" iyz="0.0000005" izz="0.002" />
        </inertial>
        <visual>
            <geometry>
                <mesh filename="../meshes/front_right_hip.dae" />
            </geometry>
        </visual>
        <collision>
          <origin rpy="1.57079632679 0 0" xyz="0 0 0"/>
          <geometry>
            <cylinder length="0.16" radius="0.046"/>
          </geometry>
        </collision>
    </link>
    <joint name="front_right_hip_x" type="revolute">
        <origin xyz="0.29785 -0.05500 0.00000" rpy="0 0 0" />
        <axis xyz="1 0 0" />
        <parent link="body" />
        <child link="front_right_hip" />
        <limit effort="1000" velocity="1000.00" lower="-0.78539816339744827899" upper="0.78539816339744827899" />
    </joint>
    <link name="front_right_upper_leg">
        <inertial>
            <origin rpy="0 0 0" xyz="0.002 0.01 -0.08" />
            <mass value="2.3" />
            <inertia ixx="0.03" ixy="0.00009" ixz="0.0005" iyy="0.03" iyz="-0.002" izz="0.003" />
        </inertial>

        <visual>
            <geometry>
                <mesh filename="../meshes/front_right_upper_leg.dae" />
            </geometry>
        </visual>

        <collision>
          <origin rpy="0 1.57079632679 0" xyz="0 0 -0.1"/>
          <geometry>
            <box size="0.44 0.12 0.12"/>
          </geometry>
        </collision>
    </link>
    <joint name="front_right_hip_y" type="revolute">
        <origin xyz="0.0 -0.110945 0.0" rpy="0 0 0" />
        <axis xyz="0 1 0" />
        <parent link="front_right_hip" />
        <child link="front_right_upper_leg" />
        <limit effort="1000" velocity="1000.00" lower="-0.89884456477707963539" upper="2.2951079663725435509" />
    </joint>
    <link name="front_right_lower_leg">
        <inertial>
            <origin rpy="0 0 0" xyz="0.006 -0.00002 -0.2" />
            <mass value="0.33" />
            <inertia ixx="0.007" ixy="-0.00000006" ixz="0.00007" iyy="0.007" iyz="-0.000001" izz="0.0001" />
        </inertial>
        <visual>
            <geometry>
                <mesh filename="../meshes/front_right_lower_leg.dae" />
            </geometry>
        </visual>
        <collision>
          <origin rpy="0 1.57079632679 0" xyz="0 0 -0.1"/>
          <geometry>
            <box size="0.44 0.1 0.1"/>
          </geometry>
        </collision>
    </link>
    <joint name="front_right_knee" type="revolute">
        <origin xyz="0.025 0.000 -0.3205" rpy="0 0 0" />
        <axis xyz="0 1 0" />
        <parent link="front_right_upper_leg" />
        <child link="front_right_lower_leg" />
        <limit effort="1000" velocity="1000.00" lower="-2.7929" upper="-0.247563" />
    </joint>
    <transmission name="front_right_hip_x">
    <type>transmission_interface/SimpleTransmission</type>
    <joint name="front_right_hip_x">
      <hardwareInterface>hardware_interface/EffortJointInterface</hardwareInterface>
    </joint>
    <actuator name="front_right_hip__xmotor">
      <hardwareInterface>hardware_interface/EffortJointInterface</hardwareInterface>
      <mechanicalReduction>1</mechanicalReduction>
    </actuator>
  </transmission>
  <transmission name="front_right_hip_y_tran">
    <type>transmission_interface/SimpleTransmission</type>
    <joint name="front_right_hip_x">
      <hardwareInterface>hardware_interface/EffortJointInterface</hardwareInterface>
    </joint>
    <actuator name="front_right_hip_y_motor">
      <hardwareInterface>hardware_interface/EffortJointInterface</hardwareInterface>
      <mechanicalReduction>1</mechanicalReduction>
    </actuator>
  </transmission>
  <transmission name="front_right_knee_tran">
    <type>transmission_interface/SimpleTransmission</type>
    <joint name="front_right_knee">
      <hardwareInterface>hardware_interface/EffortJointInterface</hardwareInterface>
    </joint>
    <actuator name="front_right_knee_motor">
      <hardwareInterface>hardware_interface/EffortJointInterface</hardwareInterface>
      <mechanicalReduction>1</mechanicalReduction>
    </actuator>
  </transmission>
    <link name="front_left_hip">
        <inertial>
            <origin rpy="0 0 0" xyz="0.02 0.0009 -0.000009" />
            <mass value="1.1" />
            <inertia ixx="0.001" ixy="-0.0002" ixz="0.0000004" iyy="0.002" iyz="-0.0000005" izz="0.002" />
        </inertial>
        <visual>
            <geometry>
                <mesh filename="../meshes/front_left_hip.dae" />
            </geometry>
        </visual>
        <collision>
          <origin rpy="1.57079632679 0 0" xyz="0 0 0"/>
          <geometry>
            <cylinder length="0.16" radius="0.06"/>
          </geometry>
        </collision>
    </link>
    <joint name="front_left_hip_x" type="revolute">
        <origin xyz="0.29785 0.05500 0.00000" rpy="0 0 0" />
        <axis xyz="1 0 0" />
        <parent link="body" />
        <child link="front_left_hip" />
        <limit effort="1000" velocity="1000.00" lower="-0.78539816339744827899" upper="0.78539816339744827899" />
    </joint>
    <link name="front_left_upper_leg">
        <inertial>
            <origin rpy="0 0 0" xyz="0.002 -0.01 -0.08" />
            <mass value="2.3" />
            <inertia ixx="0.03" ixy="-0.00009" ixz="0.0005" iyy="0.03" iyz="0.002" izz="0.003" />
        </inertial>
        <visual>
            <geometry>
                <mesh filename="../meshes/front_left_upper_leg.dae" />
            </geometry>
        </visual>
        <collision>
          <origin rpy="0 1.57079632679 0" xyz="0 0 -0.1"/>
          <geometry>
            <box size="0.44 0.12 0.12"/>
          </geometry>
        </collision>
    </link>
    <joint name="front_left_hip_y" type="revolute">
        <origin xyz="0.0 0.110945 0.0" rpy="0 0 0" />
        <axis xyz="0 1 0" />
        <parent link="front_left_hip" />
        <child link="front_left_upper_leg" />
        <limit effort="1000" velocity="1000.00" lower="-0.89884456477707963539" upper="2.2951079663725435509" />
    </joint>
    <link name="front_left_lower_leg">
        <inertial>
            <origin rpy="0 0 0" xyz="0.006 0.00002 -0.2" />
            <mass value="0.33" />
            <inertia ixx="0.007" ixy="0.00000006" ixz="0.00007" iyy="0.007" iyz="0.000001" izz="0.0001" />
        </inertial>
        <visual>
            <geometry>
                <mesh filename="../meshes/front_left_lower_leg.dae" />
            </geometry>
        </visual>
        <collision>
          <origin rpy="0 1.57079632679 0" xyz="0 0 -0.1"/>
          <geometry>
            <box size="0.44 0.1 0.1"/>
          </geometry>
        </collision>
    </link>
    <joint name="front_left_knee" type="revolute">
        <origin xyz="0.025 0.000 -0.3205" rpy="0 0 0" />
        <axis xyz="0 1 0" />
        <parent link="front_left_upper_leg" />
        <child link="front_left_lower_leg" />
        <limit effort="1000" velocity="1000.00" lower="-2.7929" upper="-0.254801" />
    </joint>
    <transmission name="front_left_hip_x">
    <type>transmission_interface/SimpleTransmission</type>
    <joint name="front_left_hip_x">
      <hardwareInterface>hardware_interface/EffortJointInterface</hardwareInterface>
    </joint>
    <actuator name="front_left_hip__xmotor">
      <hardwareInterface>hardware_interface/EffortJointInterface</hardwareInterface>
      <mechanicalReduction>1</mechanicalReduction>
    </actuator>
  </transmission>
  <transmission name="front_left_hip_y_tran">
    <type>transmission_interface/SimpleTransmission</type>
    <joint name="front_left_hip_x">
      <hardwareInterface>hardware_interface/EffortJointInterface</hardwareInterface>
    </joint>
    <actuator name="front_left_hip_y_motor">
      <hardwareInterface>hardware_interface/EffortJointInterface</hardwareInterface>
      <mechanicalReduction>1</mechanicalReduction>
    </actuator>
  </transmission>
  <transmission name="front_left_knee_tran">
    <type>transmission_interface/SimpleTransmission</type>
    <joint name="front_left_knee">
      <hardwareInterface>hardware_interface/EffortJointInterface</hardwareInterface>
    </joint>
    <actuator name="front_left_knee_motor">
      <hardwareInterface>hardware_interface/EffortJointInterface</hardwareInterface>
      <mechanicalReduction>1</mechanicalReduction>
    </actuator>
  </transmission>
  <link name="rear_right_hip">
        <inertial>
            <origin rpy="0 0 0" xyz="0.02 -0.0009 -0.000009" />
            <mass value="1.1" />
            <inertia ixx="0.001" ixy="0.0002" ixz="0.0000004" iyy="0.002" iyz="0.0000005" izz="0.002" />
        </inertial>
        <visual>
            <geometry>
                <mesh filename="../meshes/rear_right_hip.dae" />
            </geometry>
        </visual>
        <collision>
          <origin rpy="1.57079632679 0 0" xyz="0 0 0"/>
          <geometry>
            <cylinder length="0.16" radius="0.06"/>
          </geometry>
        </collision>
    </link>
    <joint name="rear_right_hip_x" type="revolute">
        <origin xyz="-0.29785 -0.05500 0.00000" rpy="0 0 0" />
        <axis xyz="1 0 0" />
        <parent link="body" />
        <child link="rear_right_hip" />
        <limit effort="1000" velocity="1000.00" lower="-0.78539816339744827899" upper="0.78539816339744827899" />
    </joint>
    <link name="rear_right_upper_leg">
        <inertial>
            <origin rpy="0 0 0" xyz="0.002 0.01 -0.08" />
            <mass value="2.3" />
            <inertia ixx="0.03" ixy="0.00009" ixz="0.0005" iyy="0.03" iyz="-0.002" izz="0.003" />
        </inertial>
        <visual>
            <geometry>
                <mesh filename="../meshes/rear_right_upper_leg.dae" />
            </geometry>
        </visual>
        <collision>
          <origin rpy="0 1.57079632679 0" xyz="0 0 -0.1"/>
          <geometry>
            <box size="0.44 0.12 0.12"/>
          </geometry>
        </collision>
    </link>
    <joint name="rear_right_hip_y" type="revolute">
        <origin xyz="0.0 -0.110945 0.0" rpy="0 0 0" />
        <axis xyz="0 1 0" />
        <parent link="rear_right_hip" />
        <child link="rear_right_upper_leg" />
        <limit effort="1000" velocity="1000.00" lower="-0.89884456477707963539" upper="2.2951079663725435509" />
    </joint>
    <link name="rear_right_lower_leg">
        <inertial>
            <origin rpy="0 0 0" xyz="0.006 -0.00002 -0.2" />
            <mass value="0.33" />
            <inertia ixx="0.007" ixy="-0.00000006" ixz="0.00007" iyy="0.007" iyz="-0.000001" izz="0.0001" />
        </inertial>
        <visual>
            <geometry>
                <mesh filename="../meshes/rear_right_lower_leg.dae" />
            </geometry>
        </visual>
        <collision>
          <origin rpy="0 1.57079632679 0" xyz="0 0 -0.1"/>
          <geometry>
            <box size="0.44 0.1 0.1"/>
          </geometry>
        </collision>
    </link>
    <joint name="rear_right_knee" type="revolute">
        <origin xyz="0.025 0.000 -0.3205" rpy="0 0 0" />
        <axis xyz="0 1 0" />
        <parent link="rear_right_upper_leg" />
        <child link="rear_right_lower_leg" />
        <limit effort="1000" velocity="1000.00" lower="-2.7929" upper="-0.257725" />
    </joint>
    <transmission name="rear_right_hip_x">
    <type>transmission_interface/SimpleTransmission</type>
    <joint name="rear_right_hip_x">
      <hardwareInterface>hardware_interface/EffortJointInterface</hardwareInterface>
    </joint>
    <actuator name="rear_right_hip__xmotor">
      <hardwareInterface>hardware_interface/EffortJointInterface</hardwareInterface>
      <mechanicalReduction>1</mechanicalReduction>
    </actuator>
  </transmission>
  <transmission name="rear_right_hip_y_tran">
    <type>transmission_interface/SimpleTransmission</type>
    <joint name="rear_right_hip_x">
      <hardwareInterface>hardware_interface/EffortJointInterface</hardwareInterface>
    </joint>
    <actuator name="rear_right_hip_y_motor">
      <hardwareInterface>hardware_interface/EffortJointInterface</hardwareInterface>
      <mechanicalReduction>1</mechanicalReduction>
    </actuator>
  </transmission>
  <transmission name="rear_right_knee_tran">
    <type>transmission_interface/SimpleTransmission</type>
    <joint name="rear_right_knee">
      <hardwareInterface>hardware_interface/EffortJointInterface</hardwareInterface>
    </joint>
    <actuator name="rear_right_knee_motor">
      <hardwareInterface>hardware_interface/EffortJointInterface</hardwareInterface>
      <mechanicalReduction>1</mechanicalReduction>
    </actuator>
  </transmission>
    <link name="rear_left_hip">
        <inertial>
            <origin rpy="0 0 0" xyz="0.02 0.0009 -0.000009" />
            <mass value="1.1" />
            <inertia ixx="0.001" ixy="-0.0002" ixz="0.0000004" iyy="0.002" iyz="-0.0000005" izz="0.002" />
        </inertial>
        <visual>
            <geometry>
                <mesh filename="../meshes/rear_left_hip.dae" />
            </geometry>
        </visual>
        <collision>
          <origin rpy="1.57079632679 0 0" xyz="0 0 0"/>
          <geometry>
            <cylinder length="0.16" radius="0.06"/>
          </geometry>
        </collision>
    </link>
    <joint name="rear_left_hip_x" type="revolute">
        <origin xyz="-0.29785 0.05500 0.00000" rpy="0 0 0" />
        <axis xyz="1 0 0" />
        <parent link="body" />
        <child link="rear_left_hip" />
        <limit effort="1000" velocity="1000.00" lower="-0.78539816339744827899" upper="0.78539816339744827899" />
    </joint>
    <link name="rear_left_upper_leg">
        <inertial>
            <origin rpy="0 0 0" xyz="0.002 -0.01 -0.08" />
            <mass value="2.3" />
            <inertia ixx="0.03" ixy="-0.00009" ixz="0.0005" iyy="0.03" iyz="0.002" izz="0.003" />
        </inertial>
        <visual>
            <geometry>
                <mesh filename="../meshes/rear_left_upper_leg.dae" />
            </geometry>
        </visual>
        <collision>
          <origin rpy="0 1.57079632679 0" xyz="0 0 -0.1"/>
          <geometry>
            <box size="0.44 0.12 0.12"/>
          </geometry>
        </collision>
    </link>
    <joint name="rear_left_hip_y" type="revolute">
        <origin xyz="0.0 0.110945 0.0" rpy="0 0 0" />
        <axis xyz="0 1 0" />
        <parent link="rear_left_hip" />
        <child link="rear_left_upper_leg" />
        <limit effort="1000" velocity="1000.00" lower="-0.89884456477707963539" upper="2.2951079663725435509" />
    </joint>
    <link name="rear_left_lower_leg">
        <inertial>
            <origin rpy="0 0 0" xyz="0.006 0.00002 -0.2" />
            <mass value="0.33" />
            <inertia ixx="0.007" ixy="0.00000006" ixz="0.00007" iyy="0.007" iyz="0.000001" izz="0.0001" />
        </inertial>
        <visual>
            <geometry>
                <mesh filename="../meshes/rear_left_lower_leg.dae" />
            </geometry>
        </visual>
        <collision>
          <origin rpy="0 1.57079632679 0" xyz="0 0 -0.1"/>
          <geometry>
            <box size="0.44 0.1 0.1"/>
          </geometry>
        </collision>
    </link>
    <joint name="rear_left_knee" type="revolute">
        <origin xyz="0.025 0.000 -0.3205" rpy="0 0 0" />
        <axis xyz="0 1 0" />
        <parent link="rear_left_upper_leg" />
        <child link="rear_left_lower_leg" />
        <limit effort="1000" velocity="1000.00" lower="-2.7929" upper="-0.267153" />
    </joint>
    <transmission name="rear_left_hip_x">
    <type>transmission_interface/SimpleTransmission</type>
    <joint name="rear_left_hip_x">
      <hardwareInterface>hardware_interface/EffortJointInterface</hardwareInterface>
    </joint>
    <actuator name="rear_left_hip__xmotor">
      <hardwareInterface>hardware_interface/EffortJointInterface</hardwareInterface>
      <mechanicalReduction>1</mechanicalReduction>
    </actuator>
  </transmission>
  <transmission name="rear_left_hip_y_tran">
    <type>transmission_interface/SimpleTransmission</type>
    <joint name="rear_left_hip_x">
      <hardwareInterface>hardware_interface/EffortJointInterface</hardwareInterface>
    </joint>
    <actuator name="rear_left_hip_y_motor">
      <hardwareInterface>hardware_interface/EffortJointInterface</hardwareInterface>
      <mechanicalReduction>1</mechanicalReduction>
    </actuator>
  </transmission>
  <transmission name="rear_left_knee_tran">
    <type>transmission_interface/SimpleTransmission</type>
    <joint name="rear_right_knee">
      <hardwareInterface>hardware_interface/EffortJointInterface</hardwareInterface>
    </joint>
    <actuator name="rear_left_knee_motor">
      <hardwareInterface>hardware_interface/EffortJointInterface</hardwareInterface>
      <mechanicalReduction>1</mechanicalReduction>
    </actuator>
  </transmission>
    <link name="eyes">
    <inertial>
      <mass value="0.001"/>
      <origin xyz="0 0 0"/>
      <inertia ixx="0.0001" ixy="0.0" ixz="0.0" iyy="0.0001" iyz="0.0" izz="0.0001"/>
    </inertial>
  </link>
  <joint name="eye_joint" type="fixed">
   <origin rpy="0 0 0" xyz="0.1778 0 0.0762"/>
    <parent link="base_link"/>
    <child link="eyes"/>
  </joint>

    <!-- Addon modules: pack_mount, lidar_mount, velodyne -->
    <!-- 
    <joint name="pack_mount_joint" type="fixed">
      <parent link="base_link"/>
      <child link="pack_mount"/>
      <origin xyz="-0.019986 0 0.093662" rpy="0 0 0"/>
    </joint>

    <link name="pack_mount">
      <visual>
        <geometry>
          <mesh filename="../meshes/pack_top.dae"/>
        </geometry>
      </visual>
      <visual>
        <geometry>
          <mesh filename="../meshes/pack_body.dae"/>
        </geometry>
      </visual>
      <collision>
        <geometry>
          <mesh filename="../meshes/pack_body.dae"/>
        </geometry>
      </collision>
    </link>

      <!-- 
      <joint name="lidar_mount_joint" type="fixed">
        <parent link="pack_mount"/>
        <child link="lidar_mount"/>
        <origin xyz="0.015 0 0.149285" rpy="0 0 0"/>
      </joint>

      <link name="lidar_mount">
        <visual>
          <geometry>
            <mesh filename="../meshes/lidar_mount.dae"/>
          </geometry>
        </visual>
        <collision>
          <geometry>
            <mesh filename="../meshes/lidar_mount_collision.stl"/>
          </geometry>
        </collision>
      </link>

        <!-- 
        <joint name="velodyne_mount_joint" type="fixed">
          <parent link="lidar_mount"/>
          <child link="velodyne_mount"/>
          <origin xyz="0 0 0" rpy="0 0 0"/>
        </joint>
        <link name="velodyne_mount">
          <visual>
            <geometry>
              <mesh filename="../meshes/velo.dae"/>
            </geometry>
          </visual>
          <collision>
            <geometry>
              <mesh filename="../meshes/velo_collision.stl"/>
            </geometry>
          </collision>
        </link>

        <joint name="velodyne_joint" type="fixed">
          <parent link="velodyne_mount"/>
          <child link="velodyne"/>
          <origin xyz="0 0 0.0377" rpy="0 0 0"/>
        </joint>
        <link name="velodyne"/>
        -->
      -->
    -->

</robot>
